[2022-03-22 18:00:08,517] {taskinstance.py:669} INFO - Dependencies all met for <TaskInstance: bigquery_data_load.load_data 2022-03-22T17:00:00+00:00 [queued]>
[2022-03-22 18:00:08,558] {taskinstance.py:669} INFO - Dependencies all met for <TaskInstance: bigquery_data_load.load_data 2022-03-22T17:00:00+00:00 [queued]>
[2022-03-22 18:00:08,559] {taskinstance.py:879} INFO - 
--------------------------------------------------------------------------------
[2022-03-22 18:00:08,560] {taskinstance.py:880} INFO - Starting attempt 1 of 1
[2022-03-22 18:00:08,560] {taskinstance.py:881} INFO - 
--------------------------------------------------------------------------------
[2022-03-22 18:00:08,715] {taskinstance.py:900} INFO - Executing <Task(GoogleCloudStorageToBigQueryOperator): load_data> on 2022-03-22T17:00:00+00:00
[2022-03-22 18:00:08,724] {standard_task_runner.py:53} INFO - Started process 1656 to run task
[2022-03-22 18:00:09,001] {logging_mixin.py:112} INFO - Running %s on host %s <TaskInstance: bigquery_data_load.load_data 2022-03-22T17:00:00+00:00 [running]> DESKTOP-NRCNVOU.localdomain
[2022-03-22 18:00:09,101] {logging_mixin.py:112} INFO - [2022-03-22 18:00:09,100] {gcp_api_base_hook.py:146} INFO - Getting connection using `google.auth.default()` since no key file is defined for hook.
[2022-03-22 18:00:12,111] {logging_mixin.py:112} INFO - [2022-03-22 18:00:12,111] {_metadata.py:99} WARNING - Compute Engine Metadata server unavailable on attempt 1 of 3. Reason: timed out
[2022-03-22 18:00:15,116] {logging_mixin.py:112} INFO - [2022-03-22 18:00:15,116] {_metadata.py:99} WARNING - Compute Engine Metadata server unavailable on attempt 2 of 3. Reason: timed out
[2022-03-22 18:00:18,122] {logging_mixin.py:112} INFO - [2022-03-22 18:00:18,121] {_metadata.py:99} WARNING - Compute Engine Metadata server unavailable on attempt 3 of 3. Reason: timed out
[2022-03-22 18:00:18,123] {logging_mixin.py:112} INFO - [2022-03-22 18:00:18,123] {_default.py:286} WARNING - Authentication failed using Compute Engine authentication due to unavailable metadata server.
[2022-03-22 18:00:18,125] {taskinstance.py:1145} ERROR - Could not automatically determine credentials. Please set GOOGLE_APPLICATION_CREDENTIALS or explicitly create credentials and re-run the application. For more information, please see https://cloud.google.com/docs/authentication/getting-started
Traceback (most recent call last):
  File "/home/collid/.local/lib/python3.8/site-packages/airflow/models/taskinstance.py", line 983, in _run_raw_task
    result = task_copy.execute(context=context)
  File "/home/collid/.local/lib/python3.8/site-packages/airflow/contrib/operators/gcs_to_bq.py", line 246, in execute
    conn = bq_hook.get_conn()
  File "/home/collid/.local/lib/python3.8/site-packages/airflow/contrib/hooks/bigquery_hook.py", line 68, in get_conn
    service = self.get_service()
  File "/home/collid/.local/lib/python3.8/site-packages/airflow/contrib/hooks/bigquery_hook.py", line 82, in get_service
    http_authorized = self._authorize()
  File "/home/collid/.local/lib/python3.8/site-packages/airflow/contrib/hooks/gcp_api_base_hook.py", line 193, in _authorize
    credentials = self._get_credentials()
  File "/home/collid/.local/lib/python3.8/site-packages/airflow/contrib/hooks/gcp_api_base_hook.py", line 148, in _get_credentials
    credentials, _ = google.auth.default(scopes=scopes)
  File "/home/collid/.local/lib/python3.8/site-packages/google/auth/_default.py", line 488, in default
    raise exceptions.DefaultCredentialsError(_HELP_MESSAGE)
google.auth.exceptions.DefaultCredentialsError: Could not automatically determine credentials. Please set GOOGLE_APPLICATION_CREDENTIALS or explicitly create credentials and re-run the application. For more information, please see https://cloud.google.com/docs/authentication/getting-started
[2022-03-22 18:00:18,131] {taskinstance.py:1189} INFO - Marking task as FAILED.dag_id=bigquery_data_load, task_id=load_data, execution_date=20220322T170000, start_date=20220322T180008, end_date=20220322T180018
[2022-03-22 18:00:18,396] {logging_mixin.py:112} INFO - [2022-03-22 18:00:18,395] {local_task_job.py:103} INFO - Task exited with return code 1
